Workbook

Sheet 彙整
A1: 夏季奧運獎牌榜
A2: 從2008年至2012年

Sheet 2004年夏季奧運
A1: 2004年雅典奧運獎牌榜
A2: 主辦國家/地區：希臘
A3: 洲際 | B3: 國家地區(編碼) | C3: 獎牌總數 | D3: 金牌 | E3: 銀牌 | F3: 銅牌
A4: 大洋洲 | B4: 澳洲(AUS) | C4: =SUM(D4:F4) -> 50 | D4: 17 | E4: 16 | F4: 17
A5: 大洋洲 | B5: 紐西蘭(NZL) | C5: =SUM(D5:F5) -> 5 | D5: 3 | E5: 2 | F5: 0
A6: 北美洲 | B6: 美國(USA) | C6: =SUM(D6:F6) -> 101 | D6: 36 | E6: 39 | F6: 26
A7: 北美洲 | B7: 古巴(CUB) | C7: =SUM(D7:F7) -> 27 | D7: 9 | E7: 7 | F7: 11
A8: 北美洲 | B8: 加拿大(CAN) | C8: =SUM(D8:F8) -> 12 | D8: 3 | E8: 6 | F8: 3
A9: 北美洲 | B9: 牙買加(JAM) | C9: =SUM(D9:F9) -> 5 | D9: 2 | E9: 1 | F9: 2
A10: 北美洲 | B10: 巴哈馬(BAH) | C10: =SUM(D10:F10) -> 2 | D10: 1 | E10: 0 | F10: 1
A11: 北美洲 | B11: 多明尼加共和國(DOM) | C11: =SUM(D11:F11) -> 1 | D11: 1 | E11: 0 | F11: 0
A12: 北美洲 | B12: 墨西哥(MEX) | C12: =SUM(D12:F12) -> 4 | D12: 0 | E12: 3 | F12: 1
A13: 北美洲 | B13: 千里達及托巴哥(TRI) | C13: =SUM(D13:F13) -> 1 | D13: 0 | E13: 0 | F13: 1
A14: 亞洲 | B14: 中國(CHN) | C14: =SUM(D14:F14) -> 63 | D14: 32 | E14: 17 | F14: 14
A15: 亞洲 | B15: 俄羅斯(RUS) | C15: =SUM(D15:F15) -> 90 | D15: 28 | E15: 26 | F15: 36
... A77: 歐洲 | B77: 愛沙尼亞(EST) | C77: =SUM(D77:F77) -> 3 | D77: 0 | E77: 1 | F77: 2

Sheet 2008年夏季奧運
A1: 2008年北京奧運獎牌榜
A2: 主辦國家/地區：中國
A3: 洲際 | B3: 國家地區(編碼) | C3: 獎牌總數 | D3: 金牌 | E3: 銀牌 | F3: 銅牌
A4: 大洋洲 | B4: 澳洲(AUS) | C4: =SUM(D4:F4) -> 46 | D4: 14 | E4: 15 | F4: 17
A5: 大洋洲 | B5: 紐西蘭(NZL) | C5: =SUM(D5:F5) -> 9 | D5: 3 | E5: 2 | F5: 4
A6: 大洋洲 | B6: 薩摩亞(SAM) | C6: =SUM(D6:F6) -> 1 | D6: 0 | E6: 1 | F6: 0
A7: 北美洲 | B7: 美國(USA) | C7: =SUM(D7:F7) -> 112 | D7: 36 | E7: 39 | F7: 37
A8: 北美洲 | B8: 牙買加(JAM) | C8: =SUM(D8:F8) -> 10 | D8: 5 | E8: 3 | F8: 2
A9: 北美洲 | B9: 加拿大(CAN) | C9: =SUM(D9:F9) -> 20 | D9: 3 | E9: 9 | F9: 8
A10: 北美洲 | B10: 古巴(CUB) | C10: =SUM(D10:F10) -> 27 | D10: 2 | E10: 10 | F10: 15
A11: 北美洲 | B11: 墨西哥(MEX) | C11: =SUM(D11:F11) -> 3 | D11: 2 | E11: 0 | F11: 1
A12: 北美洲 | B12: 多明尼加共和國(DOM) | C12: =SUM(D12:F12) -> 2 | D12: 1 | E12: 1 | F12: 0
A13: 北美洲 | B13: 千里達及托巴哥(TRI) | C13: =SUM(D13:F13) -> 2 | D13: 1 | E13: 1 | F13: 0
A14: 北美洲 | B14: 巴拿馬(PAN) | C14: =SUM(D14:F14) -> 1 | D14: 1 | E14: 0 | F14: 0
A15: 北美洲 | B15: 巴哈馬(BAH) | C15: =SUM(D15:F15) -> 2 | D15: 0 | E15: 1 | F15: 1
... A90: 歐洲 | B90: 摩爾多瓦(MDA) | C90: =SUM(D90:F90) -> 1 | D90: 0 | E90: 0 | F90: 1

Sheet 2012年夏季奧運
A1: 2012年倫敦奧運獎牌榜
A2: 主辦國家/地區：英國
A3: 洲際 | B3: 國家地區(編碼) | C3: 獎牌總數 | D3: 金牌 | E3: 銀牌 | F3: 銅牌
A4: 大洋洲 | B4: 澳洲(AUS) | C4: =SUM(D4:F4) -> 35 | D4: 8 | E4: 15 | F4: 12
A5: 大洋洲 | B5: 紐西蘭(NZL) | C5: =SUM(D5:F5) -> 13 | D5: 6 | E5: 2 | F5: 5
A6: 北美洲 | B6: 美國(USA) | C6: =SUM(D6:F6) -> 103 | D6: 46 | E6: 28 | F6: 29
A7: 北美洲 | B7: 古巴(CUB) | C7: =SUM(D7:F7) -> 15 | D7: 5 | E7: 3 | F7: 7
A8: 北美洲 | B8: 牙買加(JAM) | C8: =SUM(D8:F8) -> 12 | D8: 4 | E8: 4 | F8: 4
A9: 北美洲 | B9: 加拿大(CAN) | C9: =SUM(D9:F9) -> 18 | D9: 1 | E9: 6 | F9: 11
A10: 北美洲 | B10: 墨西哥(MEX) | C10: =SUM(D10:F10) -> 7 | D10: 1 | E10: 3 | F10: 3
A11: 北美洲 | B11: 千里達及托巴哥(TRI) | C11: =SUM(D11:F11) -> 4 | D11: 1 | E11: 1 | F11: 2
A12: 北美洲 | B12: 多明尼加共和國(DOM) | C12: =SUM(D12:F12) -> 2 | D12: 1 | E12: 1 | F12: 0
A13: 北美洲 | B13: 巴哈馬(BAH) | C13: =SUM(D13:F13) -> 1 | D13: 1 | E13: 0 | F13: 0
A14: 北美洲 | B14: 格瑞那達(GRN) | C14: =SUM(D14:F14) -> 1 | D14: 1 | E14: 0 | F14: 0
A15: 北美洲 | B15: 波多黎各(PUR) | C15: =SUM(D15:F15) -> 2 | D15: 0 | E15: 1 | F15: 1
... A89: 歐洲 | B89: 摩爾多瓦(MDA) | C89: =SUM(D89:F89) -> 0 | D89: 0 | E89: 0 | F89: 0

Sheet 2016年夏季奧運
A1: 2016年里約奧運獎牌榜
A2: 主辦國家/地區：巴西
A3: 洲際 | B3: 國家地區(編碼) | C3: 獎牌總數 | D3: 金牌 | E3: 銀牌 | F3: 銅牌
A4: 大洋洲 | B4: 澳洲(AUS) | C4: =SUM(D4:F4) -> 29 | D4: 8 | E4: 11 | F4: 10
A5: 大洋洲 | B5: 紐西蘭(NZL) | C5: =SUM(D5:F5) -> 18 | D5: 4 | E5: 9 | F5: 5
A6: 大洋洲 | B6: 斐濟(FIJ) | C6: =SUM(D6:F6) -> 1 | D6: 1 | E6: 0 | F6: 0
A7: 北美洲 | B7: 美國(USA) | C7: =SUM(D7:F7) -> 121 | D7: 46 | E7: 37 | F7: 38
A8: 北美洲 | B8: 牙買加(JAM) | C8: =SUM(D8:F8) -> 11 | D8: 6 | E8: 3 | F8: 2
A9: 北美洲 | B9: 古巴(CUB) | C9: =SUM(D9:F9) -> 11 | D9: 5 | E9: 2 | F9: 4
A10: 北美洲 | B10: 加拿大(CAN) | C10: =SUM(D10:F10) -> 22 | D10: 4 | E10: 3 | F10: 15
A11: 北美洲 | B11: 巴哈馬(BAH) | C11: =SUM(D11:F11) -> 2 | D11: 1 | E11: 0 | F11: 1
A12: 北美洲 | B12: 波多黎各(PUR) | C12: =SUM(D12:F12) -> 1 | D12: 1 | E12: 0 | F12: 0
A13: 北美洲 | B13: 墨西哥(MEX) | C13: =SUM(D13:F13) -> 5 | D13: 0 | E13: 3 | F13: 2
A14: 北美洲 | B14: 格瑞那達(GRN) | C14: =SUM(D14:F14) -> 1 | D14: 0 | E14: 1 | F14: 0
A15: 北美洲 | B15: 多明尼加共和國(DOM) | C15: =SUM(D15:F15) -> 1 | D15: 0 | E15: 0 | F15: 1
... A89: N/A | B89: 獨立奧林匹克運動員(IOA) | C89: =SUM(D89:F89) -> 2 | D89: 1 | E89: 0 | F89: 1

Sheet 近四屆統計
A1: 近四屆夏季奧運獎牌數統計與排名
A2: 2004、2008、2012、2016
A3: 洲際 | B3: 國家地區 | C3: 金牌數 | D3: 銀牌數 | E3: 銅牌數 | F3: 獎牌總數 | G3: 積分 | H3: 排名
A4: 大洋洲 | B4: 澳洲 | C4: 38 | D4: 56 | E4: 51 | F4: =SUM(C4:E4) -> 145 | G4: =C4*6+D4*3+E4 -> 447 | H4: 7
A5: 大洋洲 | B5: 紐西蘭 | C5: 19 | D5: 15 | E5: 19 | F5: =SUM(C5:E5) -> 53 | G5: =C5*6+D5*3+E5 -> 178 | H5: 17
A6: 大洋洲 | B6: 斐濟 | C6: 1 | D6: 0 | E6: 0 | F6: =SUM(C6:E6) -> 1 | G6: =C6*6+D6*3+E6 -> 6 | H6: 91
A7: 大洋洲 | B7: 薩摩亞 | C7: 0 | D7: 1 | E7: 0 | F7: =SUM(C7:E7) -> 1 | G7: =C7*6+D7*3+E7 -> 3 | H7: 101
A8: 北美洲 | B8: 美國 | C8: 174 | D8: 132 | E8: 133 | F8: =SUM(C8:E8) -> 439 | G8: =C8*6+D8*3+E8 -> 1573 | H8: 1
A9: 北美洲 | B9: 古巴 | C9: 17 | D9: 18 | E9: 33 | F9: =SUM(C9:E9) -> 68 | G9: =C9*6+D9*3+E9 -> 189 | H9: 16
A10: 北美洲 | B10: 加拿大 | C10: 9 | D10: 24 | E10: 45 | F10: =SUM(C10:E10) -> 78 | G10: =C10*6+D10*3+E10 -> 171 | H10: 18
A11: 北美洲 | B11: 牙買加 | C11: 19 | D11: 14 | E11: 12 | F11: =SUM(C11:E11) -> 45 | G11: =C11*6+D11*3+E11 -> 168 | H11: 19
A12: 北美洲 | B12: 墨西哥 | C12: 4 | D12: 9 | E12: 9 | F12: =SUM(C12:E12) -> 22 | G12: =C12*6+D12*3+E12 -> 60 | H12: 40
A13: 北美洲 | B13: 千里達及托巴哥 | C13: 3 | D13: 3 | E13: 5 | F13: =SUM(C13:E13) -> 11 | G13: =C13*6+D13*3+E13 -> 32 | H13: 55
A14: 北美洲 | B14: 多明尼加共和國 | C14: 3 | D14: 3 | E14: 1 | F14: =SUM(C14:E14) -> 7 | G14: =C14*6+D14*3+E14 -> 28 | H14: 57
A15: 北美洲 | B15: 巴哈馬 | C15: 3 | D15: 1 | E15: 2 | F15: =SUM(C15:E15) -> 6 | G15: =C15*6+D15*3+E15 -> 23 | H15: 62
... A112: N/A | B112: 獨立奧林匹克運動員 | C112: 1 | D112: 0 | E112: 1 | F112: =SUM(C112:E112) -> 2 | G112: =C112*6+D112*3+E112 -> 7 | H112: 81

Sheet 奧運會員
A1: 洲際 | B1: 編碼 | C1: 國家地區
A2: 大洋洲 | B2: AUS | C2: 澳洲
A3: 大洋洲 | B3: NZL | C3: 紐西蘭
A4: 大洋洲 | B4: SAM | C4: 薩摩亞
A5: 大洋洲 | B5: FIJ | C5: 斐濟
A6: 北美洲 | B6: USA | C6: 美國
A7: 北美洲 | B7: CUB | C7: 古巴
A8: 北美洲 | B8: CAN | C8: 加拿大
A9: 北美洲 | B9: JAM | C9: 牙買加
A10: 北美洲 | B10: BAH | C10: 巴哈馬
A11: 北美洲 | B11: DOM | C11: 多明尼加共和國
A12: 北美洲 | B12: MEX | C12: 墨西哥
... A116: N/A | B116: IOA | C116: 獨立奧林匹克運動員

Sheet 預購票樞紐分析
A1: 洲際 | B1: (全部)
A2: 國家地區 | B2: (全部)
A4: 列標籤 | B4: 預購張數
A5: 2017年 | B5: 55513
A6: 2018年 | B6: 65156
A7: 2019年 | B7: 70370
A8: 總計 | B8: 191039

Sheet 奧運預售票統計
A1: 東京奧運預售票統計
A2: 2021年東京奧運各國預售票統計
A3: 洲際 | B3: 國家地區 | C3: 年度 | D3: 季別 | E3: 月份 | F3: 張數
A4: 1北美洲 | B4: 美國 | C4: 2017年 | D4: 第1季 | E4: 1月 | F4: 214
A5: 1北美洲 | B5: 美國 | C5: 2017年 | D5: 第1季 | E5: 2月 | F5: 219
A6: 1北美洲 | B6: 美國 | C6: 2017年 | D6: 第1季 | E6: 3月 | F6: 231
A7: 1北美洲 | B7: 美國 | C7: 2017年 | D7: 第2季 | E7: 4月 | F7: 239
A8: 1北美洲 | B8: 美國 | C8: 2017年 | D8: 第2季 | E8: 5月 | F8: 211
A9: 1北美洲 | B9: 美國 | C9: 2017年 | D9: 第2季 | E9: 6月 | F9: 214
A10: 1北美洲 | B10: 美國 | C10: 2017年 | D10: 第3季 | E10: 7月 | F10: 222
A11: 1北美洲 | B11: 美國 | C11: 2017年 | D11: 第3季 | E11: 8月 | F11: 279
A12: 1北美洲 | B12: 美國 | C12: 2017年 | D12: 第3季 | E12: 9月 | F12: 293
A13: 1北美洲 | B13: 美國 | C13: 2017年 | D13: 第4季 | E13: 10月 | F13: 267
A14: 1北美洲 | B14: 美國 | C14: 2017年 | D14: 第4季 | E14: 11月 | F14: 299
A15: 1北美洲 | B15: 美國 | C15: 2017年 | D15: 第4季 | E15: 12月 | F15: 297
... A4107: 6非洲 | B4107: 蒲隆地 | C4107: 2019年 | D4107: 第4季 | E4107: 12月 | F4107: 4

Sheet 統計
A1: 年份 | B1: 國家地區 | C1: 編碼 | D1: 金牌 | E1: 銀牌 | F1: 銅牌 | G1: 洲際 | H1: 獎牌總數 | K1: 國家地區 | L1: 年份 | M1: 加總 - 金牌 | N1: 加總 - 銀牌 | O1: 加總 - 銅牌
A2: 2004年 | B2: 美國 | C2: USA | D2: 46 | E2: 28 | F2: 29 | G2: =INDEX(奧運會員!$A$2:$A$116,MATCH(B2,奧運會員!$C$2:$C$116,0)) -> 北美洲 | H2: =SUM(D2:F2) -> 103 | K2: 千里達及托巴哥 | M2: 3 | N2: 3 | O2: 5
A3: 2004年 | B3: 中國 | C3: CHN | D3: 38 | E3: 29 | F3: 21 | G3: =INDEX(奧運會員!$A$2:$A$116,MATCH(B3,奧運會員!$C$2:$C$116,0)) -> 亞洲 | H3: =SUM(D3:F3) -> 88 | K3: 土耳其 | M3: 4 | N3: 10 | O3: 9
A4: 2004年 | B4: 英國 | C4: GBR | D4: 29 | E4: 17 | F4: 19 | G4: =INDEX(奧運會員!$A$2:$A$116,MATCH(B4,奧運會員!$C$2:$C$116,0)) -> 歐洲 | H4: =SUM(D4:F4) -> 65 | K4: 中國 | M4: 150 | N4: 98 | O4: 98
A5: 2004年 | B5: 俄羅斯 | C5: RUS | D5: 20 | E5: 19 | F5: 31 | G5: =INDEX(奧運會員!$A$2:$A$116,MATCH(B5,奧運會員!$C$2:$C$116,0)) -> 亞洲 | H5: =SUM(D5:F5) -> 70 | K5: 中國香港 | M5: 0 | N5: 0 | O5: 2
A6: 2004年 | B6: 韓國 | C6: KOR | D6: 13 | E6: 9 | F6: 8 | G6: =INDEX(奧運會員!$A$2:$A$116,MATCH(B6,奧運會員!$C$2:$C$116,0)) -> 亞洲 | H6: =SUM(D6:F6) -> 30 | K6: 中華台北 | M6: 4 | N6: 1 | O6: 6
A7: 2004年 | B7: 德國 | C7: GER | D7: 11 | E7: 19 | F7: 14 | G7: =INDEX(奧運會員!$A$2:$A$116,MATCH(B7,奧運會員!$C$2:$C$116,0)) -> 歐洲 | H7: =SUM(D7:F7) -> 44 | K7: 丹麥 | M7: 8 | N7: 16 | O7: 16
A8: 2004年 | B8: 法國 | C8: FRA | D8: 11 | E8: 11 | F8: 13 | G8: =INDEX(奧運會員!$A$2:$A$116,MATCH(B8,奧運會員!$C$2:$C$116,0)) -> 歐洲 | H8: =SUM(D8:F8) -> 35 | K8: 厄瓜多 | M8: 0 | N8: 1 | O8: 0
A9: 2004年 | B9: 澳洲 | C9: AUS | D9: 8 | E9: 15 | F9: 12 | G9: =INDEX(奧運會員!$A$2:$A$116,MATCH(B9,奧運會員!$C$2:$C$116,0)) -> 大洋洲 | H9: =SUM(D9:F9) -> 35 | K9: 巴西 | M9: 16 | N9: 20 | O9: 34
A10: 2004年 | B10: 義大利 | C10: ITA | D10: 8 | E10: 9 | F10: 11 | G10: =INDEX(奧運會員!$A$2:$A$116,MATCH(B10,奧運會員!$C$2:$C$116,0)) -> 歐洲 | H10: =SUM(D10:F10) -> 28 | K10: 巴林 | M10: 1 | N10: 1 | O10: 2
A11: 2004年 | B11: 匈牙利 | C11: HUN | D11: 8 | E11: 4 | F11: 6 | G11: =INDEX(奧運會員!$A$2:$A$116,MATCH(B11,奧運會員!$C$2:$C$116,0)) -> 歐洲 | H11: =SUM(D11:F11) -> 18 | K11: 巴哈馬 | M11: 3 | N11: 1 | O11: 2
A12: 2004年 | B12: 日本 | C12: JPN | D12: 7 | E12: 14 | F12: 17 | G12: =INDEX(奧運會員!$A$2:$A$116,MATCH(B12,奧運會員!$C$2:$C$116,0)) -> 亞洲 | H12: =SUM(D12:F12) -> 38 | K12: 巴拿馬 | M12: 1 | N12: 0 | O12: 0
A13: 2004年 | B13: 荷蘭 | C13: NED | D13: 6 | E13: 6 | F13: 8 | G13: =INDEX(奧運會員!$A$2:$A$116,MATCH(B13,奧運會員!$C$2:$C$116,0)) -> 歐洲 | H13: =SUM(D13:F13) -> 20 | K13: 日本 | M13: 35 | N13: 43 | O13: 64
... A111: 2008年 | B111: 捷克 | C111: CZE | D111: 3 | E111: 3 | F111: 1 | G111: =INDEX(奧運會員!$A$2:$A$116,MATCH(B111,奧運會員!$C$2:$C$116,0)) -> 歐洲 | H111: =SUM(D111:F111) -> 7 | K111: 總計 | M111: 1202 | N111: 1208 | O111: 1413
A112: 2008年 | B112: 紐西蘭 | C112: NZL | D112: 3 | E112: 2 | F112: 4 | G112: =INDEX(奧運會員!$A$2:$A$116,MATCH(B112,奧運會員!$C$2:$C$116,0)) -> 大洋洲 | H112: =SUM(D112:F112) -> 9
A113: 2008年 | B113: 喬治亞 | C113: GEO | D113: 3 | E113: 2 | F113: 2 | G113: =INDEX(奧運會員!$A$2:$A$116,MATCH(B113,奧運會員!$C$2:$C$116,0)) -> 亞洲 | H113: =SUM(D113:F113) -> 7
A114: 2008年 | B114: 斯洛伐克 | C114: SVK | D114: 3 | E114: 2 | F114: 1 | G114: =INDEX(奧運會員!$A$2:$A$116,MATCH(B114,奧運會員!$C$2:$C$116,0)) -> 歐洲 | H114: =SUM(D114:F114) -> 6
A115: 2008年 | B115: 古巴 | C115: CUB | D115: 2 | E115: 10 | F115: 15 | G115: =INDEX(奧運會員!$A$2:$A$116,MATCH(B115,奧運會員!$C$2:$C$116,0)) -> 北美洲 | H115: =SUM(D115:F115) -> 27
A116: 2008年 | B116: 丹麥 | C116: DEN | D116: 2 | E116: 2 | F116: 3 | G116: =INDEX(奧運會員!$A$2:$A$116,MATCH(B116,奧運會員!$C$2:$C$116,0)) -> 歐洲 | H116: =SUM(D116:F116) -> 7
A117: 2008年 | B117: 朝鮮 | C117: PRK | D117: 2 | E117: 2 | F117: 2 | G117: =INDEX(奧運會員!$A$2:$A$116,MATCH(B117,奧運會員!$C$2:$C$116,0)) -> 亞洲 | H117: =SUM(D117:F117) -> 6
A118: 2008年 | B118: 泰國 | C118: THA | D118: 2 | E118: 2 | F118: 1 | G118: =INDEX(奧運會員!$A$2:$A$116,MATCH(B118,奧運會員!$C$2:$C$116,0)) -> 亞洲 | H118: =SUM(D118:F118) -> 5
A119: 2008年 | B119: 蒙古 | C119: MGL | D119: 2 | E119: 2 | F119: 0 | G119: =INDEX(奧運會員!$A$2:$A$116,MATCH(B119,奧運會員!$C$2:$C$116,0)) -> 亞洲 | H119: =SUM(D119:F119) -> 4
A120: 2008年 | B120: 瑞士 | C120: SUI | D120: 2 | E120: 1 | F120: 4 | G120: =INDEX(奧運會員!$A$2:$A$116,MATCH(B120,奧運會員!$C$2:$C$116,0)) -> 歐洲 | H120: =SUM(D120:F120) -> 7
A121: 2008年 | B121: 阿根廷 | C121: ARG | D121: 2 | E121: 0 | F121: 4 | G121: =INDEX(奧運會員!$A$2:$A$116,MATCH(B121,奧運會員!$C$2:$C$116,0)) -> 南美洲 | H121: =SUM(D121:F121) -> 6
A122: 2008年 | B122: 墨西哥 | C122: MEX | D122: 2 | E122: 0 | F122: 1 | G122: =INDEX(奧運會員!$A$2:$A$116,MATCH(B122,奧運會員!$C$2:$C$116,0)) -> 北美洲 | H122: =SUM(D122:F122) -> 3
A123: 2008年 | B123: 比利時 | C123: BEL | D123: 2 | E123: 0 | F123: 0 | G123: =INDEX(奧運會員!$A$2:$A$116,MATCH(B123,奧運會員!$C$2:$C$116,0)) -> 歐洲 | H123: =SUM(D123:F123) -> 2
... A346: 2016年 | B346: 阿拉伯聯合大公國 | C346: UAE | D346: 0 | E346: 0 | F346: 1 | G346: =INDEX(奧運會員!$A$2:$A$116,MATCH(B346,奧運會員!$C$2:$C$116,0)) -> 亞洲 | H346: =SUM(D346:F346) -> 1

Sheet 五大洲
A1: 國家地區 | B1: 首都 | C1: 區域 | D1: 備註
A2: 阿爾及利亞 | B2: 阿爾及爾 | C2: 非洲
A3: 安哥拉 | B3: 魯安達 | C3: 非洲
A4: 貝南 | B4: 新港 | C4: 非洲
A5: 波札那 | B5: 嘉柏隆里 | C5: 非洲
A6: 英屬印度洋領地 | B6: 迪亞哥加西亞島 | C6: 非洲 | D6: 英國海外領地
A7: 布吉納法索 | B7: 瓦加杜古 | C7: 非洲
A8: 蒲隆地 | B8: 基特加 | C8: 非洲
A9: 喀麥隆 | B9: 雅恩德 | C9: 非洲
A10: 維德角 | B10: 培亞 | C10: 非洲
A11: 中非共和國 | B11: 班基 | C11: 非洲
A12: 查德 | B12: 恩加美納 | C12: 非洲
A13: 葛摩 | B13: 莫洛尼 | C13: 非洲
A14: 剛果(金) | B14: 金夏沙 | C14: 非洲
A15: 剛果共和國 | B15: 布拉薩市 | C15: 非洲
A16: 象牙海岸 | B16: 雅穆索戈 | C16: 非洲
A17: 吉布地 | B17: 吉布地市 | C17: 非洲
A18: 埃及 | B18: 開羅 | C18: 非洲
... A35: 模里西斯 | B35: 路易士港 | C35: 非洲
A36: 馬約特 | B36: 馬穆楚 | C36: 非洲 | D36: 法國行政區劃
A37: 摩洛哥 | B37: 拉巴特 | C37: 非洲
A38: 莫三比克 | B38: 馬布多 | C38: 非洲
A39: 納米比亞 | B39: 溫荷克 | C39: 非洲
A40: 尼日 | B40: 尼阿美 | C40: 非洲
A41: 奈及利亞 | B41: 阿布加 | C41: 非洲
A42: 留尼旺 | B42: 聖丹尼 | C42: 非洲 | D42: 法國行政區劃
A43: 盧安達 | B43: 吉佳利 | C43: 非洲
A44: 聖赫倫那 | B44: 詹姆斯敦 | C44: 非洲 | D44: 包括阿森松島：英國海外領土
A45: 聖多美普林西比 | B45: 聖多美 | C45: 非洲
A46: 塞內加爾 | B46: 達卡 | C46: 非洲
A47: 塞席爾 | B47: 維多利亞 | C47: 非洲
A48: 獅子山 | B48: 自由城 | C48: 非洲
A49: 索馬利亞 | B49: 摩加迪休 | C49: 非洲
A50: 南非 | B50: 普利托利亞、開普敦、布隆泉 | C50: 非洲
A51: 蘇丹 | B51: 喀土穆 | C51: 非洲
A52: 史瓦帝尼 | B52: 墨巴本、洛班巴 | C52: 非洲
A53: 坦尚尼亞 | B53: 杜篤瑪 | C53: 非洲
A54: 多哥 | B54: 洛梅 | C54: 非洲
A55: 突尼西亞 | B55: 突尼西亞市 | C55: 非洲
A56: 烏干達 | B56: 康培拉 | C56: 非洲
...
